Workbook

Sheet Income Statement
A1: LULULEMON ATHLETICA INC.
A2: Pro Forma Income Statement ($ in millions)
B4: FY2024A | C4: FY2025E | D4: FY2026E | E4: FY2027E
A5: Net Revenue | B5: 10570 | C5: 11200 | D5: 12100 | E5: 13000
A6: YoY Growth % | C6: =B5/B5-1 | D6: =D5/C5-1 | E6: =E5/D5-1
A8: Cost of Goods Sold | B8: =B5*0.43 | C8: =C5*0.43 | D8: =D5*0.43 | E8: =E5*0.43
A9: Gross Profit | B9: =B5-B8 | C9: =C5-C8 | D9: =D5-D8 | E9: =E5-E8
A10: Gross Margin % | B10: =B9/B5 | C10: =C9/C5 | D10: =D9/D5 | E10: =E9/E5
A12: Selling, General & Administrative | B12: =B5*0.33 | C12: =C5*0.33 | D12: =D5*0.33 | E12: =E5*0.33
A13: Depreciation & Amortization | B13: =B5*0.04 | C13: =C5*0.04 | D13: =D5*0.04 | E13: =E5*0.04
A14: Total Operating Expenses | B14: =B12+B13 | C14: =C12+C13 | D14: =D12+D13 | E14: =E12+E13
A16: Operating Income (EBIT) | B16: =B9-B14 | C16: =C9-C14 | D16: =D9-D14 | E16: =E9-E14
A17: Operating Margin % | B17: =B16/B5 | C17: =C16/C5 | D17: =D16/D5 | E17: =E16/E5
A19: Interest Expense | B19: -15 | C19: -15 | D19: -15 | E19: -15
A20: Interest Income | B20: 50 | C20: 55 | D20: 60 | E20: 65
A21: Other Income/(Expense) | B21: 10 | C21: 10 | D21: 10 | E21: 10
A23: Pre-Tax Income (EBT) | B23: =B16+B19+B20+B21 | C23: =C16+C19+C20+C21 | D23: =D16+D19+D20+D21 | E23: =E16+E19+E20+E21
A24: Income Tax Expense | B24: =B23*0.27 | C24: =C23*0.27 | D24: =D23*0.27 | E24: =E23*0.27
A25: Effective Tax Rate | B25: =B24/B23 | C25: =C24/C23 | D25: =D24/D23 | E25: =E24/E23
A27: Net Income | B27: =B23-B24 | C27: =C23-C24 | D27: =D23-D24 | E27: =E23-E24
A28: Net Margin % | B28: =B27/B5 | C28: =C27/C5 | D28: =D27/D5 | E28: =E27/E5
A30: Shares Outstanding (M) | B30: 125 | C30: 124 | D30: 123 | E30: 122
A31: Earnings Per Share (EPS) | B31: =B27/B30 | C31: =C27/C30 | D31: =D27/D30 | E31: =E27/E30

Sheet Balance Sheet
A1: LULULEMON ATHLETICA INC.
A2: Pro Forma Balance Sheet ($ in millions)
B4: FY2024A | C4: FY2025E | D4: FY2026E | E4: FY2027E
A5: ASSETS
A6: Current Assets:
A7: Cash & Cash Equivalents | B7: 1850 | C7: =C30 | D7: =D30 | E7: =E30
A8: Short-term Investments | B8: 200 | C8: 220 | D8: 240 | E8: 260
A9: Accounts Receivable | B9: ='Income Statement'!B5*5/365 | C9: ='Income Statement'!C5*5/365 | D9: ='Income Statement'!D5*5/365 | E9: ='Income Statement'!E5*5/365
A10: Inventory | B10: ='Income Statement'!B8*120/365 | C10: ='Income Statement'!C8*120/365 | D10: ='Income Statement'!D8*120/365 | E10: ='Income Statement'!E8*120/365
A11: Prepaid Expenses | B11: 150 | C11: 160 | D11: 170 | E11: 180
A12: Total Current Assets | B12: =SUM(B7:B11) | C12: =SUM(C7:C11) | D12: =SUM(D7:D11) | E12: =SUM(E7:E11)
A14: Non-Current Assets:
A15: Property, Plant & Equipment (Gross) | B15: 2800 | C15: =B15+'Income Statement'!C5*0.05 | D15: =C15+'Income Statement'!D5*0.05 | E15: =D15+'Income Statement'!E5*0.05
A16: Accumulated Depreciation | B16: -900 | C16: =B16-'Income Statement'!C13 | D16: =C16-'Income Statement'!D13 | E16: =D16-'Income Statement'!E13
A17: Net PP&E | B17: =B15+B16 | C17: =C15+C16 | D17: =D15+D16 | E17: =E15+E16
A18: Operating Lease ROU Assets | B18: 1200 | C18: 1250 | D18: 1300 | E18: 1350
A19: Goodwill & Intangibles | B19: 350 | C19: 350 | D19: 350 | E19: 350
A20: Other Non-Current Assets | B20: 180 | C20: 190 | D20: 200 | E20: 210
A21: Total Non-Current Assets | B21: =SUM(B17:B20) | C21: =SUM(C17:C20) | D21: =SUM(D17:D20) | E21: =SUM(E17:E20)
A23: TOTAL ASSETS | B23: =B12+B21 | C23: =C12+C21 | D23: =D12+D21 | E23: =E12+E21
A25: LIABILITIES
A26: Current Liabilities:
A27: Accounts Payable | B27: ='Income Statement'!B8*30/365 | C27: ='Income Statement'!C8*30/365 | D27: ='Income Statement'!D8*30/365 | E27: ='Income Statement'!E8*30/365
A28: Accrued Liabilities | B28: 400 | C28: 420 | D28: 450 | E28: 480
A29: Deferred Revenue | B29: 200 | C29: 210 | D29: 225 | E29: 240
A30: Current Lease Liabilities | B30: 180 | C30: 190 | D30: 200 | E30: 210
A31: Other Current Liabilities | B31: 100 | C31: 105 | D31: 110 | E31: 115
A32: Total Current Liabilities | B32: =SUM(B27:B31) | C32: =SUM(C27:C31) | D32: =SUM(D27:D31) | E32: =E27+E28+E29+E30+E31
A34: Non-Current Liabilities:
A35: Long-term Debt | B35: 400 | C35: 400 | D35: 400 | E35: 400
A36: Non-Current Lease Liabilities | B36: 1100 | C36: 1150 | D36: 1200 | E36: 1250
A37: Deferred Tax Liabilities | B37: 150 | C37: 160 | D37: 170 | E37: 180
A38: Other Non-Current Liabilities | B38: 80 | C38: 85 | D38: 90 | E38: 95
A39: Total Non-Current Liabilities | B39: =SUM(B35:B38) | C39: =SUM(C35:C38) | D39: =SUM(D35:D38) | E39: =SUM(E35:E38)
A41: TOTAL LIABILITIES | B41: =B32+B39 | C41: =C32+C39 | D41: =D32+D39 | E41: =E32+E39
A43: SHAREHOLDERS' EQUITY
A44: Common Stock | B44: 1 | C44: 1 | D44: 1 | E44: 1
A45: Additional Paid-in Capital | B45: 650 | C45: 700 | D45: 750 | E45: 800
A46: Retained Earnings | B46: =B23-B41-B44-B45 | C46: =B46+'Income Statement'!C27 | D46: =C46+'Income Statement'!D27 | E46: =D46+'Income Statement'!E27
A47: Treasury Stock | B47: -1500 | C47: -1600 | D47: -1700 | E47: -1800
...

Sheet Cash Flow Statement
A1: LULULEMON ATHLETICA INC.
A2: Pro Forma Cash Flow Statement ($ in millions)
B4: FY2024A | C4: FY2025E | D4: FY2026E | E4: FY2027E
A5: OPERATING ACTIVITIES
A6: Net Income | B6: ='Income Statement'!B27 | C6: ='Income Statement'!C27 | D6: ='Income Statement'!D27 | E6: ='Income Statement'!E27
A7: Adjustments to reconcile to cash:
A8: Depreciation & Amortization | B8: ='Income Statement'!B13 | C8: ='Income Statement'!C13 | D8: ='Income Statement'!D13 | E8: ='Income Statement'!E13
A9: Stock-Based Compensation | B9: 120 | C9: 130 | D9: 140 | E9: 150
A10: Deferred Income Taxes | B10: 15 | C10: 10 | D10: 10 | E10: 10
A11: Changes in Working Capital:
A12: (Increase)/Decrease in Receivables | C12: ='Balance Sheet'!B9-'Balance Sheet'!C9 | D12: ='Balance Sheet'!C9-'Balance Sheet'!D9 | E12: ='Balance Sheet'!D9-'Balance Sheet'!E9
A13: (Increase)/Decrease in Inventory | C13: ='Balance Sheet'!B10-'Balance Sheet'!C10 | D13: ='Balance Sheet'!C10-'Balance Sheet'!D10 | E13: ='Balance Sheet'!D10-'Balance Sheet'!E10
A14: (Increase)/Decrease in Prepaid | C14: ='Balance Sheet'!B11-'Balance Sheet'!C11 | D14: ='Balance Sheet'!C11-'Balance Sheet'!D11 | E14: ='Balance Sheet'!D11-'Balance Sheet'!E11
A15: Increase/(Decrease) in Payables | C15: ='Balance Sheet'!C27-'Balance Sheet'!B27 | D15: ='Balance Sheet'!D27-'Balance Sheet'!C27 | E15: ='Balance Sheet'!E27-'Balance Sheet'!D27
A16: Increase/(Decrease) in Accrued Liab | C16: ='Balance Sheet'!C28-'Balance Sheet'!B28 | D16: ='Balance Sheet'!D28-'Balance Sheet'!C28 | E16: ='Balance Sheet'!E28-'Balance Sheet'!D28
A17: Other Working Capital Changes | B17: 50 | C17: 30 | D17: 35 | E17: 40
A18: Net Cash from Operating Activities | B18: =SUM(B6:B17) | C18: =SUM(C6:C17) | D18: =SUM(D6:D17) | E18: =SUM(E6:E17)
A20: INVESTING ACTIVITIES
A21: Capital Expenditures (CapEx) | B21: =-'Income Statement'!B5*0.05 | C21: =-'Income Statement'!C5*0.05 | D21: =-'Income Statement'!D5*0.05 | E21: =-'Income Statement'!E5*0.05
A22: Purchases of Investments | B22: -50 | C22: -60 | D22: -70 | E22: -80
A23: Other Investing Activities | B23: -20 | C23: -25 | D23: -25 | E23: -25
A24: Net Cash from Investing Activities | B24: =SUM(B21:B23) | C24: =SUM(C21:C23) | D24: =SUM(D21:D23) | E24: =SUM(E21:E23)
A26: FINANCING ACTIVITIES
A27: Repurchase of Common Stock | B27: -800 | C27: -100 | D27: -100 | E27: -100
A28: Stock Option Exercises | B28: 30 | C28: 35 | D28: 40 | E28: 45
A29: Debt Repayments | B29: 0 | C29: 0 | D29: 0 | E29: 0
A30: Other Financing Activities | B30: -15 | C30: -15 | D30: -15 | E30: -15
A31: Net Cash from Financing Activities | B31: =SUM(B27:B30) | C31: =SUM(C27:C30) | D31: =SUM(D27:D30) | E31: =SUM(E27:E30)
A33: Net Change in Cash | B33: =B18+B24+B31 | C33: =C18+C24+C31 | D33: =D18+D24+D31 | E33: =E18+E24+E31
A34: Beginning Cash Balance | B34: 1500 | C34: ='Balance Sheet'!B7 | D34: ='Balance Sheet'!C7 | E34: ='Balance Sheet'!D7
A35: Ending Cash Balance | B35: =B33+B34 | C35: =C33+C34 | D35: =D33+D34 | E35: =E33+E34

Sheet Assumptions & Sources
A1: LULULEMON ATHLETICA - PRO FORMA MODEL ASSUMPTIONS & SOURCES
A4: REVENUE ESTIMATES (Street Consensus)
A5: Source | B5: Yahoo Finance Analyst Estimates, Bloomberg Terminal, Seeking Alpha
A7: Fiscal Year | B7: Revenue ($M) | C7: Growth Rate | D7: Source
A8: FY2024 (Actual) | B8: 10570 | C8: - | D8: Lululemon 10-K Annual Report
A9: FY2025E | B9: 11200 | C9: 6.0% | D9: Wall Street Consensus (Yahoo Finance)
A10: FY2026E | B10: 12100 | C10: 8.0% | D10: Wall Street Consensus (Bloomberg)
A11: FY2027E | B11: 13000 | C11: 7.4% | D11: Wall Street Consensus (FactSet)
A13: KEY OPERATING ASSUMPTIONS
A14: Gross Margin | B14: 57.0% | C14: Based on historical average and company guidance
A15: SG&A as % of Revenue | B15: 33.0% | C15: Historical trend analysis
A16: D&A as % of Revenue | B16: 4.0% | C16: Based on asset base and capex levels
A17: Tax Rate | B17: 27.0% | C17: Effective tax rate from recent filings
A19: BALANCE SHEET ASSUMPTIONS
A20: Days Sales Outstanding (DSO) | B20: 5 | C20: Minimal receivables (retail)
A21: Days Inventory Outstanding (DIO) | B21: 120 | C21: Based on historical inventory turns
A22: Days Payables Outstanding (DPO) | B22: 30 | C22: Standard industry terms
A23: CapEx as % of Revenue | B23: 5.0% | C23: Management guidance
A25: DATA ACCESSED
A26: Date | B26: February 2026
A27: Primary Sources | B27: SEC EDGAR 10-K filings, Yahoo Finance, Bloomberg Terminal
